<robot name="robot">

<!--__________________________ROBOT KLEUREN____________________________________________-->
<material name="blue">
    <color rgba="0 0 1 1"/>
</material>

<material name="black">
    <color rgba="0 0 0 1"/>
</material>

<material name="white">
    <color rgba="1 1 1 1"/>
</material>

<material name="red">
    <color rgba="0.8 0 0 1"/>
</material>

<material name="green">
    <color rgba="0 1 0 1"/>
</material>

<material name="yellow">
    <color rgba="1 1 0 1"/>
</material>

<!--__________________________LINKS_____________________________________________________-->
	<link name="base_link"> 
 		<visual> 
    		<origin xyz="0 0 0" rpy="0 0 0" /> 
    		<geometry> 
      			<mesh filename="package://kuka_description/meshes/kuka_kr5_arc/visual/Base.stl" 
				scale=".001 .001 .001"/> 
      		</geometry> 
			<material name ="red"/>
 		</visual> 
 		<collision> 
    		<origin xyz="0 0 0" rpy="0 0 0" /> 
    		<geometry> 
      			<mesh filename="package://kuka_description/meshes/kuka_kr5_arc/visual/Base.stl" 
				scale=".001 .001 .001"/> 
      		</geometry> 
 		</collision> 
	</link>	

	<link name="link1"> 
 		<visual> 
   			<origin xyz="0 0 -0.225" rpy="0 0 0" /> 
    		<geometry> 
      			<mesh filename="package://kuka_description/meshes/kuka_kr5_arc/visual/Link1.stl" 
				scale=".001 .001 .001"/> 
      		</geometry> 
			<material name ="yellow"/>
 		</visual> 
 		<collision> 
    		<origin xyz="0 0 -0.225" rpy="0 0 0" /> 
    		<geometry> 
      			<mesh filename="package://kuka_description/meshes/kuka_kr5_arc/visual/Link1.stl" 
				scale=".001 .001 .001"/> 
      		</geometry> 
 		</collision> 
	</link>

	<link name="link2"> 
 		<visual> 
    		<origin xyz="-0.180 0 -0.400" rpy="0 0 0" /> 
    		<geometry> 
      			<mesh filename="package://kuka_description/meshes/kuka_kr5_arc/visual/Link2.stl" 
				scale=".001 .001 .001"/> 
      		</geometry> 
			<material name ="green"/>
 		</visual> 
 		<collision> 
    		<origin xyz="-0.180 0 -0.400" rpy="0 0 0" /> 
    		<geometry> 
      			<mesh filename="package://kuka_description/meshes/kuka_kr5_arc/visual/Link2.stl" 
				scale=".001 .001 .001"/> 
      		</geometry> 
 		</collision> 
	</link>	

	<link name="link3"> 
 		<visual> 
    		<origin xyz="-0.180 0 -1.0" rpy="0 0 0" /> 
    		<geometry> 
      			<mesh filename="package://kuka_description/meshes/kuka_kr5_arc/visual/Link3.stl" 
				scale=".001 .001 .001"/> 
      		</geometry> 
			<material name ="blue"/>
 		</visual> 
 		<collision> 
    		<origin xyz="-0.180 0 -1.0" rpy="0 0 0" /> 
    		<geometry> 
     			<mesh filename="package://kuka_description/meshes/kuka_kr5_arc/visual/Link3.stl" 
				scale=".001 .001 .001"/> 
      		</geometry> 
 		</collision> 
	</link>			

	<link name="link4"> 
 		<visual> 
    		<origin xyz="-0.5835 0 -1.12" rpy="0 0 0" /> 
    		<geometry> 
      			<mesh filename="package://kuka_description/meshes/kuka_kr5_arc/visual/Link4.stl" 
				scale=".001 .001 .001"/> 
      		</geometry>
			<material name ="red"/> 
 		</visual> 
 		<collision> 
    		<origin xyz="-0.5835 0 -1.12" rpy="0 0 0" /> 
    		<geometry> 
      			<mesh filename="package://kuka_description/meshes/kuka_kr5_arc/visual/Link4.stl" 
				scale=".001 .001 .001"/> 
      		</geometry> 
 		</collision> 
	</link>	

	<link name="link5">
 		<visual> 
    		<origin xyz="-0.800 0 -1.12" rpy="0 0 0" /> 
    		<geometry> 
      			<mesh filename="package://kuka_description/meshes/kuka_kr5_arc/visual/Link5.stl" 
				scale=".001 .001 .001"/> 
      		</geometry> 
			<material name ="yellow"/>
 		</visual> 
 		<collision> 
    		<origin xyz="-0.800 0 -1.12" rpy="0 0 0" /> 
    		<geometry> 
      			<mesh filename="package://kuka_description/meshes/kuka_kr5_arc/visual/Link5.stl" 
				scale=".001 .001 .001"/> 
     		</geometry> 
 		</collision>  
 	</link>	

	<link name="link6"> 
 		<visual> 
    		<origin xyz="-0.9088 0 -1.12" rpy="0 0 0" /> 
    		<geometry> 
     			 <mesh filename="package://kuka_description/meshes/kuka_kr5_arc/visual/Link6.stl" 
				scale=".001 .001 .001"/> 
      		</geometry> 
			<material name ="green"/>
     	</visual> 
 		<collision> 
    		<origin xyz="-0.9088 0 -1.12" rpy="0 0 0" /> 
    		<geometry> 
      			<mesh filename="package://kuka_description/meshes/kuka_kr5_arc/visual/Link6.stl" 
				scale=".001 .001 .001"/> 
      		</geometry> 
 		</collision> 
	</link>	

	<link name="link7"> 
 		<visual> 
    		<origin xyz="0 0 0" rpy="0 0 0" /> 
    		<geometry> 
      			<mesh filename="package://kuka_description/meshes/Welding_Torch/Assembly4_origin_tip3.stl" 
				scale=".01 .01 .01"/> 
      		</geometry> 
			<material name ="blue"/>
 		</visual> 
 		<collision> 
    		<origin xyz="0 0 0" rpy="0 0 0" /> 
    		<geometry> 
      			<mesh filename="package://kuka_description/meshes/Welding_Torch/Assembly4_origin_tip3.stl" 
				scale=".01 .01 .01"/> 
      		</geometry> 
 		</collision> 
	</link>	

	<link name="endpoint"/> 

<!--__________________________JOINTS__________________________________________________-->

	<joint name="joint_1" type="revolute">
		<parent link="base_link"/>
		<child link="link1"/>
		<origin xyz="0 0 0.225" rpy="0 0 0" />	 
  		<axis xyz="0 0 -1" />
  		<limit lower="-2.70526034" upper="2.70526034" effort="0" velocity="0" />
		<material name ="black"/>
	</joint>

	<joint name="joint_2" type="revolute">
		<parent link="link1"/>
		<child link="link2"/>
		<origin xyz="0.180 0 0.175" rpy="0 0 0" />
  		<axis xyz="0 1 0" />
 		<limit lower="-3.1415927" upper="1.13446401" effort="0" velocity="0" />
	</joint>
 
	<joint name="joint_3" type="revolute">
		<parent link="link2"/>
		<child link="link3"/>
		<origin xyz="0 0 0.600" rpy="0 0 0" />
 		<axis xyz="0 1 0" />
 		<limit lower="-0.2617994" upper="2.75762022" effort="0" velocity="0" />
	</joint>

	<joint name="joint_4" type="revolute">
		<parent link="link3"/>
		<child link="link4"/>
		<origin xyz="0.4035 0 0.120" rpy="0 0 0" />
 		<axis xyz="-1 0 0" />
  		<limit lower="-6.10865238" upper="6.10865238" effort="0" velocity="0" />
	</joint>

	<joint name="joint_5" type="revolute">
		<parent link="link4"/>
		<child link="link5"/>
		<origin xyz="0.2165 0 0" rpy="0 0 0" />
  		<axis xyz="0 1 0" />
  		<limit lower="-2.26892803" upper="2.26892803" effort="0" velocity="0" />
	</joint>
 
	<joint name="joint_6" type="revolute">
		<parent link="link5"/>
		<child link="link6"/>
		<origin xyz="0.1088 0 0" rpy="0 0 0" />
  		<axis xyz="-1 0 0" />
  		<limit lower="-6.10865238" upper="6.10865238" effort="0" velocity="0" />
	</joint>

	<joint name="joint_7" type="fixed">
		<parent link="link6"/>
		<child link="link7"/>
		<origin xyz="0.326 0 0.034" rpy="0 0 3.141529" />
	</joint>

	<joint name="joint_8" type= "fixed">
		<parent link="link7"/>
		<child link="endpoint"/>
		<origin xyz="0 0 0" rpy="0 3.92685325 0" />
	</joint>

</robot>

