<robot  name="kuka_kr5_arc">

<link name="Base"> 
 <visual> 
    <origin xyz="0 0 0" rpy="0 0 0" /> 
    <geometry> 
      <mesh filename="package://kuka_description/meshes/kuka_kr5_arc/visual/Base.stl" 
	scale=".001 .001 .001"/> 
      </geometry> 
 </visual> 
 <collision> 
    <origin xyz="0 0 0" rpy="0 0 0" /> 
    <geometry> 
      <mesh filename="package://kuka_description/meshes/kuka_kr5_arc/visual/Base.stl" 
	scale=".001 .001 .001"/> 
      </geometry> 
 </collision> 
</link>		

<link name="Link1"> 
 <visual> 
    <origin xyz="0 0 -0.225" rpy="0 0 0" /> 
    <geometry> 
      <mesh filename="package://kuka_description/meshes/kuka_kr5_arc/visual/Link1.stl" 
	scale=".001 .001 .001"/> 
      </geometry> 
 </visual> 
 <collision> 
    <origin xyz="0 0 -0.225" rpy="0 0 0" /> 
    <geometry> 
      <mesh filename="package://kuka_description/meshes/kuka_kr5_arc/visual/Link1.stl" 
	scale=".001 .001 .001"/> 
      </geometry> 
 </collision> 
</link>

<link name="Link2"> 
 <visual> 
    <origin xyz="-0.180 0 -0.400" rpy="0 0 0" /> 
    <geometry> 
      <mesh filename="package://kuka_description/meshes/kuka_kr5_arc/visual/Link2.stl" 
	scale=".001 .001 .001"/> 
      </geometry> 
 </visual> 
 <collision> 
    <origin xyz="-0.180 0 -0.400" rpy="0 0 0" /> 
    <geometry> 
      <mesh filename="package://kuka_description/meshes/kuka_kr5_arc/visual/Link2.stl" 
	scale=".001 .001 .001"/> 
      </geometry> 
 </collision> 
</link>			

<link name="Link3"> 
 <visual> 
    <origin xyz="-0.180 0 -1.0" rpy="0 0 0" /> 
    <geometry> 
      <mesh filename="package://kuka_description/meshes/kuka_kr5_arc/visual/Link3.stl" 
	scale=".001 .001 .001"/> 
      </geometry> 
 </visual> 
 <collision> 
    <origin xyz="-0.180 0 -1.0" rpy="0 0 0" /> 
    <geometry> 
      <mesh filename="package://kuka_description/meshes/kuka_kr5_arc/visual/Link3.stl" 
	scale=".001 .001 .001"/> 
      </geometry> 
 </collision> 
</link>			

<link name="Link4"> 
 <visual> 
    <origin xyz="-0.5835 0 -1.12" rpy="0 0 0" /> 
    <geometry> 
      <mesh filename="package://kuka_description/meshes/kuka_kr5_arc/visual/Link4.stl" 
	scale=".001 .001 .001"/> 
      </geometry> 
 </visual> 
 <collision> 
    <origin xyz="-0.5835 0 -1.12" rpy="0 0 0" /> 
    <geometry> 
      <mesh filename="package://kuka_description/meshes/kuka_kr5_arc/visual/Link4.stl" 
	scale=".001 .001 .001"/> 
      </geometry> 
 </collision> 
</link>	

<link name="Link5">
 <visual> 
    <origin xyz="-0.800 0 -1.12" rpy="0 0 0" /> 
    <geometry> 
      <mesh filename="package://kuka_description/meshes/kuka_kr5_arc/visual/Link5.stl" 
	scale=".001 .001 .001"/> 
      </geometry> 
 </visual> 
 <collision> 
    <origin xyz="-0.800 0 -1.12" rpy="0 0 0" /> 
    <geometry> 
      <mesh filename="package://kuka_description/meshes/kuka_kr5_arc/visual/Link5.stl" 
	scale=".001 .001 .001"/> 
      </geometry> 
 </collision>  
 </link>	

<link name="Link6"> 
 <visual> 
    <origin xyz="-0.9088 0 -1.12" rpy="0 0 0" /> 
    <geometry> 
      <mesh filename="package://kuka_description/meshes/kuka_kr5_arc/visual/Link6.stl" 
	scale=".001 .001 .001"/> 
      </geometry> 
 </visual> 
 <collision> 
    <origin xyz="-0.9088 0 -1.12" rpy="0 0 0" /> 
    <geometry> 
      <mesh filename="package://kuka_description/meshes/kuka_kr5_arc/visual/Link6.stl" 
	scale=".001 .001 .001"/> 
      </geometry> 
 </collision> 
</link>			

<link name="odom_combined"/>

<joint name="joint1" type="revolute">	
  <parent link="Base" /> 
  <child link="Link1" />
  <origin xyz="0 0 0.225" rpy="0 0 0" />	 
  <axis xyz="0 0 -1" />
  <limit lower="-2.70526034" upper="2.70526034" effort="0" velocity="0" />
</joint>

<joint name="joint2" type="revolute"> 
  <parent link="Link1" /> 
  <child link="Link2" /> 
  <origin xyz="0.180 0 0.175" rpy="0 0 0" />
  <axis xyz="0 1 0" />
  <limit lower="-3.1415927" upper="1.13446401" effort="0" velocity="0" />	
</joint>

<joint name="joint3" type="revolute"> 
  <parent link="Link2" /> 
  <child link="Link3" /> 
  <origin xyz="0 0 0.600" rpy="0 0 0" />
  <axis xyz="0 1 0" />
  <limit lower="-0.2617994" upper="2.75762022" effort="0" velocity="0" />
</joint>

<joint name="joint4" type="revolute"> 
  <parent link="Link3" /> 
  <child link="Link4" /> 
  <origin xyz="0.4035 0 0.120" rpy="0 0 0" />
  <axis xyz="-1 0 0" />
  <limit lower="-6.10865238" upper="6.10865238" effort="0" velocity="0" />
</joint>

<joint name="joint5" type="revolute"> 
  <parent link="Link4" /> 
  <child link="Link5" /> 
  <origin xyz="0.2165 0 0" rpy="0 0 0" />
  <axis xyz="0 1 0" />
  <limit lower="-2.26892803" upper="2.26892803" effort="0" velocity="0" />
</joint>

<joint name="joint6" type="revolute"> 
  <parent link="Link5" /> 
  <child link="Link6" /> 
  <origin xyz="0.1088 0 0" rpy="0 0 0" />
  <axis xyz="-1 0 0" />
  <limit lower="-6.10865238" upper="6.10865238" effort="0" velocity="0" />
</joint>

<joint name="fixed" type="fixed">
  <parent link="odom_combined"/> 
  <child link="Base"/> 
</joint>  
</robot>
