<?xml version="1.0" ?>
<!-- =================================================================================== -->
<!-- |    This document was autogenerated by xacro from kr120_with_torch.urdf.xacro    | -->
<!-- |    EDITING THIS FILE BY HAND IS NOT RECOMMENDED                                 | -->
<!-- =================================================================================== -->
<robot name="kr120_with_torch" xmlns:xacro="http://www.ros.org/wiki/xacro">
  <material name="Grey">
    <color rgba="0.5 0.5 0.5 1.0"/>
  </material>
  <!--Dummy base link-->
  <link name="base_link">
    <visual>
      <geometry>
        <box size="0.2 0.2 0.01"/>
      </geometry>
    </visual>
    <collision>
      <geometry>
        <box size="0.2 0.2 0.01"/>
      </geometry>
    </collision>
  </link>
  <!--Put kuka arm on base link-->
  <!-- LINKS -->
  <!-- base link -->
  <link name="arm_base_link">
    <inertial>
      <origin rpy="0 0 0" xyz="0 0 0"/>
      <mass value="2"/>
      <inertia ixx="0.01" ixy="0" ixz="0" iyy="0.01" iyz="0" izz="0.01"/>
    </inertial>
    <visual>
      <origin rpy="0 0 0" xyz="0 0 0"/>
      <geometry>
        <mesh filename="package://kuka_kr120_support/meshes/kr120r2500pro/visual/base_link.dae"/>
      </geometry>
    </visual>
    <collision>
      <origin rpy="0 0 0" xyz="0 0 0"/>
      <geometry>
        <mesh filename="package://kuka_kr120_support/meshes/kr120r2500pro/collision/base_link.stl"/>
      </geometry>
    </collision>
  </link>
  <!-- link 1 (A1) -->
  <link name="arm_link_1">
    <inertial>
      <origin rpy="0 0 0" xyz="0 0 0"/>
      <mass value="2"/>
      <inertia ixx="0.01" ixy="0" ixz="0" iyy="0.01" iyz="0" izz="0.01"/>
    </inertial>
    <visual>
      <origin rpy="0 0 0" xyz="0 0 0"/>
      <geometry>
        <mesh filename="package://kuka_kr120_support/meshes/kr120r2500pro/visual/link_1.dae"/>
      </geometry>
    </visual>
    <collision>
      <origin rpy="0 0 0" xyz="0 0 0"/>
      <geometry>
        <mesh filename="package://kuka_kr120_support/meshes/kr120r2500pro/collision/link_1.stl"/>
      </geometry>
    </collision>
  </link>
  <!-- link 2 -->
  <link name="arm_link_2">
    <inertial>
      <origin rpy="0 0 0" xyz="0 0 0"/>
      <mass value="2"/>
      <inertia ixx="0.01" ixy="0" ixz="0" iyy="0.01" iyz="0" izz="0.01"/>
    </inertial>
    <visual>
      <origin rpy="0 0 0" xyz="0 0 0"/>
      <geometry>
        <mesh filename="package://kuka_kr120_support/meshes/kr120r2500pro/visual/link_2.dae"/>
      </geometry>
    </visual>
    <collision>
      <origin rpy="0 0 0" xyz="0 0 0"/>
      <geometry>
        <mesh filename="package://kuka_kr120_support/meshes/kr120r2500pro/collision/link_2.stl"/>
      </geometry>
    </collision>
  </link>
  <!-- link 3 -->
  <link name="arm_link_3">
    <inertial>
      <origin rpy="0 0 0" xyz="0 0 0"/>
      <mass value="2"/>
      <inertia ixx="0.01" ixy="0" ixz="0" iyy="0.01" iyz="0" izz="0.01"/>
    </inertial>
    <visual>
      <origin rpy="0 0 0" xyz="0 0 0"/>
      <geometry>
        <mesh filename="package://kuka_kr120_support/meshes/kr120r2500pro/visual/link_3.dae"/>
      </geometry>
    </visual>
    <collision>
      <origin rpy="0 0 0" xyz="0 0 0"/>
      <geometry>
        <mesh filename="package://kuka_kr120_support/meshes/kr120r2500pro/collision/link_3.stl"/>
      </geometry>
    </collision>
  </link>
  <!-- link 4 -->
  <link name="arm_link_4">
    <inertial>
      <origin rpy="0 0 0" xyz="0 0 0"/>
      <mass value="2"/>
      <inertia ixx="0.01" ixy="0" ixz="0" iyy="0.01" iyz="0" izz="0.01"/>
    </inertial>
    <visual>
      <origin rpy="0 0 0" xyz="0 0 0"/>
      <geometry>
        <mesh filename="package://kuka_kr120_support/meshes/kr120r2500pro/visual/link_4.dae"/>
      </geometry>
    </visual>
    <collision>
      <origin rpy="0 0 0" xyz="0 0 0"/>
      <geometry>
        <mesh filename="package://kuka_kr120_support/meshes/kr120r2500pro/collision/link_4.stl"/>
      </geometry>
    </collision>
  </link>
  <!-- link 5 -->
  <link name="arm_link_5">
    <inertial>
      <origin rpy="0 0 0" xyz="0 0 0"/>
      <mass value="2"/>
      <inertia ixx="0.01" ixy="0" ixz="0" iyy="0.01" iyz="0" izz="0.01"/>
    </inertial>
    <visual>
      <origin rpy="0 0 0" xyz="0 0 0"/>
      <geometry>
        <mesh filename="package://kuka_kr120_support/meshes/kr120r2500pro/visual/link_5.dae"/>
      </geometry>
    </visual>
    <collision>
      <origin rpy="0 0 0" xyz="0 0 0"/>
      <geometry>
        <mesh filename="package://kuka_kr120_support/meshes/kr120r2500pro/collision/link_5.stl"/>
      </geometry>
    </collision>
  </link>
  <!-- link 6 -->
  <link name="arm_link_6">
    <inertial>
      <origin rpy="0 0 0" xyz="0 0 0"/>
      <mass value="2"/>
      <inertia ixx="0.01" ixy="0" ixz="0" iyy="0.01" iyz="0" izz="0.01"/>
    </inertial>
    <visual>
      <origin rpy="0 0 0" xyz="0 0 0"/>
      <geometry>
        <mesh filename="package://kuka_kr120_support/meshes/kr120r2500pro/visual/link_6.dae"/>
      </geometry>
    </visual>
    <collision>
      <origin rpy="0 0 0" xyz="0 0 0"/>
      <geometry>
        <mesh filename="package://kuka_kr120_support/meshes/kr120r2500pro/collision/link_6.stl"/>
      </geometry>
    </collision>
  </link>
  <!-- tool 0 -->
  <!-- This frame corresponds to the $FLANGE coordinate system in KUKA KRC controllers. -->
  <link name="arm_tool0"/>
  <!-- END LINKS -->
  <!-- JOINTS -->
  <!-- joint 1 (A1) -->
  <joint name="arm_joint_a1" type="revolute">
    <origin rpy="0 0 0" xyz="0 0 0.675"/>
    <parent link="arm_base_link"/>
    <child link="arm_link_1"/>
    <axis xyz="0 0 -1"/>
    <limit effort="0" lower="-3.22885911619" upper="3.22885911619" velocity="2.72271363311"/>
  </joint>
  <!-- joint 2 (A2) -->
  <joint name="arm_joint_a2" type="revolute">
    <origin rpy="0 0 0" xyz="0.35 0 0"/>
    <parent link="arm_link_1"/>
    <child link="arm_link_2"/>
    <axis xyz="0 1 0"/>
    <limit effort="0" lower="-2.70526034059" upper="0.610865238198" velocity="2.72271363311"/>
  </joint>
  <!-- joint 3 (A3) -->
  <joint name="arm_joint_a3" type="revolute">
    <origin rpy="0 0 0" xyz="1.150 0 0"/>
    <parent link="arm_link_2"/>
    <child link="arm_link_3"/>
    <axis xyz="0 1 0"/>
    <limit effort="0" lower="-2.26892802759" upper="2.68780704807" velocity="2.72271363311"/>
  </joint>
  <!-- joint 4 (A4) -->
  <joint name="arm_joint_a4" type="revolute">
    <origin rpy="0 0 0" xyz="1.0 0 -0.041"/>
    <parent link="arm_link_3"/>
    <child link="arm_link_4"/>
    <axis xyz="-1 0 0"/>
    <limit effort="0" lower="-6.10865238198" upper="6.10865238198" velocity="5.75958653158"/>
  </joint>
  <!-- joint 5 (A5) -->
  <joint name="arm_joint_a5" type="revolute">
    <origin rpy="0 0 0" xyz="0 0 0"/>
    <parent link="arm_link_4"/>
    <child link="arm_link_5"/>
    <axis xyz="0 1 0"/>
    <limit effort="0" lower="-2.26892802759" upper="2.26892802759" velocity="5.75958653158"/>
  </joint>
  <!-- joint 6 (A6) -->
  <joint name="arm_joint_a6" type="revolute">
    <origin rpy="0 0 0" xyz="0 0 0"/>
    <parent link="arm_link_5"/>
    <child link="arm_link_6"/>
    <axis xyz="-1 0 0"/>
    <limit effort="0" lower="-6.10865238198" upper="6.10865238198" velocity="10.7337748998"/>
  </joint>
  <!-- tool frame - fixed frame -->
  <joint name="arm_joint_a6-tool0" type="fixed">
    <parent link="arm_link_6"/>
    <child link="arm_tool0"/>
    <origin rpy="0 1.57079632679 0" xyz="0.215 0 0"/>
  </joint>
  <!-- END JOINTS -->
  <!-- ROS base_link to KUKA $ROBROOT coordinate system transform -->
  <link name="arm_base"/>
  <joint name="arm_base_link-base" type="fixed">
    <origin rpy="0 0 0" xyz="0 0 0"/>
    <parent link="arm_base_link"/>
    <child link="arm_base"/>
  </joint>
  <joint name="base_link_to_arm_base_link" type="fixed">
    <parent link="base_link"/>
    <child link="arm_base_link"/>
  </joint>
  <!--Add welding torch-->
  <link name="welding_torch">
    <visual>
      <origin rpy="0 -1.57079632679 0" xyz="0 0 0"/>
      <geometry>
        <mesh filename="package://kr120_with_torch/meshes/torch.stl" scale=".01 .01 .01"/>
      </geometry>
      <material name="Grey"/>
    </visual>
    <collision>
      <origin rpy="0 -1.57079632679 0" xyz="0 0 0"/>
      <geometry>
        <mesh filename="package://kr120_with_torch/meshes/torch.stl" scale=".01 .01 .01"/>
      </geometry>
    </collision>
  </link>
  <link name="tool_tip"/>
  <joint name="tool_to_torch" type="fixed">
    <parent link="arm_tool0"/>
    <child link="welding_torch"/>
  </joint>
  <joint name="torch_to_tip" type="fixed">
    <parent link="welding_torch"/>
    <child link="tool_tip"/>
    <origin rpy="0 0.78526059641 0" xyz="-0.034 0 0.326"/>
  </joint>
</robot>

